<?xml version="1.0" ?>
<!-- =================================================================================== -->
<!-- |    This document was autogenerated by xacro from /home/rony/er9-ros-workspace/src/ur_er9_support/er9.xacro | -->
<!-- |    EDITING THIS FILE BY HAND IS NOT RECOMMENDED                                 | -->
<!-- =================================================================================== -->
<robot name="ur_er9" xmlns:xacro="http://www.ros.org/wiki/xacro">
    <link name="base_link">
        <visual>
            <geometry>
                <mesh filename="package://ur_er9_support/meshes/visual/base.stl" />
            </geometry>
            <material name="">
                <color rgba="0 0 1 1" />
            </material>
            <origin rpy="0 0 0" xyz="0 0 0" />
        </visual>
        <collision>
            <geometry>
                <mesh filename="package://ur_er9_support/meshes/visual/base.stl" />
            </geometry>
            <origin rpy="0 0 0" xyz="0 0 0" />
        </collision>

<inertial>
            <mass value="0.1" />
            <inertia ixx="0.03" iyy="0.03" izz="0.03" ixy="0.0" ixz="0.0" iyz="0.0" />
        </inertial>

    </link>
    <link name="link1">
        <visual>
            <geometry>
                <mesh filename="package://ur_er9_support/meshes/visual/link1.stl" />
            </geometry>
            <material name="">
                <color rgba="0 0 1 1" />
            </material>
            <origin rpy="0 0 0" xyz="0 0 0" />
        </visual>
        <collision>
            <geometry>
                <mesh filename="package://ur_er9_support/meshes/visual/link1.stl" />
            </geometry>
            <origin rpy="0 0 0" xyz="0 0 0" />
        </collision>

<inertial>
            <mass value="0.1" />
            <inertia ixx="0.03" iyy="0.03" izz="0.03" ixy="0.0" ixz="0.0" iyz="0.0" />
        </inertial>

    </link>
    <joint name="joint1" type="revolute">
        <axis xyz="0 0 1" />
        <limit effort="1000.0" lower="-4.36332312999" upper="4.36332312999" velocity="1.0" />
        <origin rpy="0 0 0" xyz="0 0 0.174" />
        <parent link="base_link" />
        <child link="link1" />
    </joint>
    <link name="link2">
        <visual>
            <geometry>
                <mesh filename="package://ur_er9_support/meshes/visual/link2.stl" />
            </geometry>
            <material name="">
                <color rgba="0 0 1 1" />
            </material>
            <origin rpy="0 0 0" xyz="0 0 0" />
        </visual>
        <collision>
            <geometry>
                <mesh filename="package://ur_er9_support/meshes/visual/link2.stl" />
            </geometry>
            <origin rpy="0 0 0" xyz="0 0 0" />
        </collision>

<inertial>
            <mass value="0.1" />
            <inertia ixx="0.03" iyy="0.03" izz="0.03" ixy="0.0" ixz="0.0" iyz="0.0" />
        </inertial>

    </link>
    <joint name="joint2" type="revolute">
        <axis xyz="0 1 0" />
        <limit effort="1000.0" lower="-2.61799387799" upper="1.0471975512" velocity="1.0" />
        <origin rpy="0 0 0" xyz="0.07 -0.1 0.164" />
        <parent link="link1" />
        <child link="link2" />
    </joint>
    <link name="link3">
        <visual>
            <geometry>
                <mesh filename="package://ur_er9_support/meshes/visual/link3.stl" />
            </geometry>
            <material name="">
                <color rgba="0 0 1 1" />
            </material>
            <origin rpy="0 0 0" xyz="0 0 0" />
        </visual>
        <collision>
            <geometry>
                <mesh filename="package://ur_er9_support/meshes/visual/link3.stl" />
            </geometry>
            <origin rpy="0 0 0" xyz="0 0 0" />
        </collision>

<inertial>
            <mass value="0.1" />
            <inertia ixx="0.03" iyy="0.03" izz="0.03" ixy="0.0" ixz="0.0" iyz="0.0" />
        </inertial>

    </link>
    <joint name="joint3" type="revolute">
        <axis xyz="0 1 0" />
        <limit effort="1000.0" lower="-3.92699081699" upper="3.92699081699" velocity="1.0" />
        <origin rpy="0 0 0" xyz="0.290 0.018 0" />
        <parent link="link2" />
        <child link="link3" />
    </joint>
    <link name="link4">
        <visual>
            <geometry>
                <mesh filename="package://ur_er9_support/meshes/visual/link4.stl" />
            </geometry>
            <material name="">
                <color rgba="0 0 1 1" />
            </material>
            <origin rpy="0 0 0" xyz="0 0 0" />
        </visual>
        <collision>
            <geometry>
                <mesh filename="package://ur_er9_support/meshes/visual/link4.stl" />
            </geometry>
            <origin rpy="0 0 0" xyz="0 0 0" />
        </collision>

<inertial>
            <mass value="0.1" />
            <inertia ixx="0.03" iyy="0.03" izz="0.03" ixy="0.0" ixz="0.0" iyz="0.0" />
        </inertial>

    </link>
    <joint name="joint4" type="revolute">
        <axis xyz="0 1 0" />
        <limit effort="1000.0" lower="-3.14159265359" upper="3.14159265359" velocity="1.0" />
        <origin rpy="0 0 0" xyz="0.239 0.041 0" />
        <parent link="link3" />
        <child link="link4" />
    </joint>
    <link name="link5">
        <visual>
            <geometry>
                <mesh filename="package://ur_er9_support/meshes/visual/link5.stl" />
            </geometry>
            <material name="">
                <color rgba="0 0 1 1" />
            </material>
            <origin rpy="0 0 0" xyz="0 0 0" />
        </visual>
        <collision>
            <geometry>
                <mesh filename="package://ur_er9_support/meshes/visual/link5.stl" />
            </geometry>
            <origin rpy="0 0 0" xyz="0 0 0" />
        </collision>

<inertial>
            <mass value="0.1" />
            <inertia ixx="0.03" iyy="0.03" izz="0.03" ixy="0.0" ixz="0.0" iyz="0.0" />
        </inertial>

    </link>
    <joint name="joint5" type="revolute">
        <axis xyz="1 0 0" />
        <limit effort="1000.0" lower="-6.28318530718" upper="6.28318530718" velocity="1.0" />
        <origin rpy="0 0 0" xyz="0.111 0 0" />
        <parent link="link4" />
        <child link="link5" />
    </joint>
    <link name="tool0" />
    <link name="base" />
    <joint name="base_link-base" type="fixed">
        <origin rpy="0 0 0" xyz="0 0 0" />
        <parent link="base_link" />
        <child link="base" />
    </joint>
    <joint name="joint5-tool0" type="fixed">
        <origin rpy="0 0 0" xyz="0.045 0 0" />
        <parent link="link5" />
        <child link="tool0" />
    </joint>

<transmission name="trans_joint1">
        <type>transmission_interface/SimpleTransmission</type>
        <joint name="joint1">
            <hardwareInterface>hardware_interface/EffortJointInterface</hardwareInterface>
        </joint>
        <actuator name="joint1_motor">
            <hardwareInterface>hardware_interface/EffortJointInterface</hardwareInterface>
            <mechanicalReduction>1</mechanicalReduction>
        </actuator>
    </transmission>
    <transmission name="trans_joint2">
        <type>transmission_interface/SimpleTransmission</type>
        <joint name="joint2">
            <hardwareInterface>hardware_interface/EffortJointInterface</hardwareInterface>
        </joint>
        <actuator name="joint2_motor">
            <hardwareInterface>hardware_interface/EffortJointInterface</hardwareInterface>
            <mechanicalReduction>1</mechanicalReduction>
        </actuator>
    </transmission>
    <transmission name="trans_joint3">
        <type>transmission_interface/SimpleTransmission</type>
        <joint name="joint3">
            <hardwareInterface>hardware_interface/EffortJointInterface</hardwareInterface>
        </joint>
        <actuator name="joint3_motor">
            <hardwareInterface>hardware_interface/EffortJointInterface</hardwareInterface>
            <mechanicalReduction>1</mechanicalReduction>
        </actuator>
    </transmission>
    <transmission name="trans_joint4">
        <type>transmission_interface/SimpleTransmission</type>
        <joint name="joint4">
            <hardwareInterface>hardware_interface/EffortJointInterface</hardwareInterface>
        </joint>
        <actuator name="joint4_motor">
            <hardwareInterface>hardware_interface/EffortJointInterface</hardwareInterface>
            <mechanicalReduction>1</mechanicalReduction>
        </actuator>
    </transmission>
    <transmission name="trans_joint5">
        <type>transmission_interface/SimpleTransmission</type>
        <joint name="joint5">
            <hardwareInterface>hardware_interface/EffortJointInterface</hardwareInterface>
        </joint>
        <actuator name="joint5_motor">
            <hardwareInterface>hardware_interface/EffortJointInterface</hardwareInterface>
            <mechanicalReduction>1</mechanicalReduction>
        </actuator>
    </transmission>
    <gazebo>
        <plugin name="gazebo_ros_control" filename="libgazebo_ros_control.so">
            <robotNamespace>/</robotNamespace>
        </plugin>
    </gazebo>
</robot>